<?xml version="1.0" encoding="utf-8"?>
<robot name="Go_manipulator">

  <material name="black">
    <color rgba="0.0 0.0 0.0 1.0"/>
  </material>
  <material name="blue">
    <color rgba="0.0 0.0 0.8 1.0"/>
  </material>
  <material name="brown">
    <color rgba="0.8706 0.8118 0.7647 1.0"/>
  </material>
  <material name="dark">
    <color rgba="0.3 0.3 0.3 1.0"/>
  </material>
  <material name="green">
    <color rgba="0.0 0.8 0.0 1.0"/>
  </material>
  <material name="grey">
    <color rgba="0.5 0.5 0.5 1.0"/>
  </material>
  <material name="light_black">
    <color rgba="0.4 0.4 0.4 1.0"/>
  </material>
  <material name="orange">
    <color rgba="1.0 0.4235 0.0392 1.0"/>
  </material>
  <material name="red">
    <color rgba="0.8 0.0 0.0 1.0"/>
  </material>
  <material name="white">
    <color rgba="1.0 1.0 1.0 1.0"/>
  </material>



  <!-- Base Link -->
  <link name="link0">
    <inertial>
      <origin xyz="-0.0676 -0.0067 0.1811" rpy="0 0 0" />
      <mass value="0.8410" />
      <inertia ixx="0.0026" ixy="2.8e-13" ixz="-4.3e-13" iyy="0.0044" iyz="-5.1e-7" izz="0.0025" />
    </inertial>
    <visual>
      <origin xyz="0 0 0" rpy="0 0 0" />
      <geometry>
        <mesh filename="package://Go_manipulator_description/meshes/base_link.STL" />
      </geometry>
      <material name="">
        <color rgba="0.75 0.75 0.75 1" />
      </material>
    </visual>
    <collision>
      <origin xyz="0 0 0" rpy="0 0 0" />
      <geometry>
        <mesh filename="package://Go_manipulator_description/meshes/base_link.STL" />
      </geometry>
    </collision>
  </link>

  <!-- Link 1 -->
  <link name="link1">
    <inertial>
      <origin xyz="0 0.0180 0.00005" rpy="0 0 0" />
      <mass value="0.4427" />
      <inertia ixx="0.0006" ixy="8.3e-21" ixz="-1.2e-13" iyy="0.0013" iyz="-6.98e-7" izz="0.0009" />
    </inertial>
    <visual>
      <origin xyz="0 0 0" rpy="0 0 0" />
      <geometry>
        <mesh filename="package://Go_manipulator_description/meshes/link1.STL" />
      </geometry>
      <material name="white"/>
    </visual>
    <collision>
      <origin xyz="0 0 0" rpy="0 0 0" />
      <geometry>
        <mesh filename="package://Go_manipulator_description/meshes/link1.STL" />
      </geometry>
    </collision>
  </link>

  <!-- Joint 1 -->
  <joint name="joint1" type="revolute">
    <origin xyz="-0.0676 -0.18 0.0207" rpy="1.5708 0 0" />
    <parent link="link0" />
    <child link="link1" />
    <axis xyz="0 1 0" />
    <limit lower="-3.14159" upper="3.14159" effort="1" velocity="1.0" />
  </joint>

  <!-- Link 2 -->
  <link name="link2">
    <inertial>
      <origin xyz="0 0.0253 0.0751" rpy="0 0 0" />
      <mass value="0.4222" />
      <inertia ixx="0.0010" ixy="-4.91e-15" ixz="1.65e-15" iyy="0.0027" iyz="-0.00027" izz="0.0020" />
    </inertial>
    <visual>
      <origin xyz="0 0 0" rpy="0 0 0" />
      <geometry>
        <mesh filename="package://Go_manipulator_description/meshes/link2.STL" />
      </geometry>
      <material name="white"/>
    </visual>
    <collision>
      <origin xyz="0 0 0" rpy="0 0 0" />
      <geometry>
        <mesh filename="package://Go_manipulator_description/meshes/link2.STL" />
      </geometry>
    </collision>
  </link>

  <!-- Joint 2 -->
  <joint name="joint2" type="revolute">
    <origin xyz="0 0.0605 0.00025" rpy="-1.2461 0 0" />
    <parent link="link1" />
    <child link="link2" />
    <axis xyz="1 0 0" />
    <limit lower="-3.14159" upper="3.14159" effort="1" velocity="1.0" />

  </joint>

  <!-- Link 3 -->
  <link name="link3">
    <inertial>
      <origin xyz="0.0010 0.0340 0.0946" rpy="0 0 0" />
      <mass value="0.3496" />
      <inertia ixx="0.0022" ixy="-1.15e-5" ixz="-3.21e-5" iyy="0.0019" iyz="-0.00065" izz="0.00032" />
    </inertial>
    <visual>
      <origin xyz="0 0 0" rpy="0 0 0" />
      <geometry>
        <mesh filename="package://Go_manipulator_description/meshes/link3.STL" />
      </geometry>
      <material name="white"/>
    </visual>
    <collision>
      <origin xyz="0 0 0" rpy="0 0 0" />
      <geometry>
        <mesh filename="package://Go_manipulator_description/meshes/link3.STL" />
      </geometry>
    </collision>
  </link>

  <!-- Joint 3 -->
  <joint name="joint3" type="revolute">
    <origin xyz="0 0.0360 0.1070" rpy="0.0142 0 0" />
    <parent link="link2" />
    <child link="link3" />
    <axis xyz="1 0 0" />
    <limit lower="-3.14159" upper="3.14159" effort="1" velocity="1.0" />

  </joint>

  <!-- Link 4 -->
  <link name="link4">
    <inertial>
      <origin xyz="-0.0225 0.0259 0.0850" rpy="0 0 0" />
      <mass value="0.3143" />
      <inertia ixx="0.0018" ixy="7.0e-6" ixz="2.29e-5" iyy="0.0016" iyz="-0.00046" izz="0.00022" />
    </inertial>
    <visual>
      <origin xyz="0 0 0" rpy="0 0 0" />
      <geometry>
        <mesh filename="package://Go_manipulator_description/meshes/link4.STL" />
      </geometry>
      <material name="white"/>
    </visual>
    <collision>
      <origin xyz="0 0 0" rpy="0 0 0" />
      <geometry>
        <mesh filename="package://Go_manipulator_description/meshes/link4.STL" />
      </geometry>
    </collision>
  </link>

  <!-- Joint 4 -->
  <joint name="joint4" type="revolute">
    <origin xyz="0 0.0738 0.2053" rpy="1.5283 0 0" />
    <parent link="link3" />
    <child link="link4" />
    <axis xyz="1 0 0" />
    <limit lower="-3.14159" upper="3.14159" effort="1" velocity="1.0" />

  </joint>

  <!-- Link 5 -->
  <link name="link5">
    <inertial>
      <origin xyz="-0.0007 -0.0543 -0.0032" rpy="0 0 0" />
      <mass value="0.2388" />
      <inertia ixx="0.0006" ixy="2.93e-6" ixz="5.84e-7" iyy="7.49e-5" iyz="-4.25e-5" izz="0.0006" />
    </inertial>
    <visual>
      <origin xyz="0 0 0" rpy="0 0 0" />
      <geometry>
        <mesh filename="package://Go_manipulator_description/meshes/link5.STL" />
      </geometry>
      <material name="white"/>
    </visual>
    <collision>
      <origin xyz="0 0 0" rpy="0 0 0" />
      <geometry>
        <mesh filename="package://Go_manipulator_description/meshes/link5.STL" />
      </geometry>
    </collision>
  </link>

  <!-- Joint 5 -->
  <joint name="joint5" type="revolute">
    <origin xyz="0 0.0583 0.1913" rpy="-0.2964 0 0" />
    <parent link="link4" />
    <child link="link5" />
    <axis xyz="1 0 0" />
    <limit lower="-3.14159" upper="3.14159" effort="1" velocity="1.0" />

  </joint>

  <!-- Gripper Base -->
  <link name="gripper_base">
    <inertial>
      <origin xyz="0.0001 -0.0283 0" rpy="0 0 0" />
      <mass value="0.0568" />
      <inertia ixx="3.21e-5" ixy="8.06e-8" ixz="-3.23e-7" iyy="2.21e-5" iyz="-6.81e-18" izz="1.67e-5" />
    </inertial>
    <visual>
      <origin xyz="0 0 0" rpy="0 0 0" />
      <geometry>
        <mesh filename="package://Go_manipulator_description/meshes/gripper_base.STL" />
      </geometry>
      <material name="white"/>
    </visual>
    <collision>
      <origin xyz="0 0 0" rpy="0 0 0" />
      <geometry>
        <mesh filename="package://Go_manipulator_description/meshes/gripper_base.STL" />
      </geometry>
    </collision>
  </link>

  <!-- Joint 6 -->
  <joint name="joint6" type="revolute">
    <origin xyz="0.0006 -0.1363 -0.0005" rpy="0 1.5708 0" />
    <parent link="link5" />
    <child link="gripper_base" />
    <axis xyz="0 1 0" />
    <limit lower="-3.14159" upper="3.14159" effort="1" velocity="1.0" />
  </joint>

  <!-- Gripper Finger 1 -->
  <link name="gripper_finger1">
    <inertial>
      <origin xyz="0.0518 -0.0832 -0.0127" rpy="0 0 0" />
      <mass value="0.0356" />
      <inertia ixx="4.53e-5" ixy="-4.95e-7" ixz="-2.13e-7" iyy="2.41e-5" iyz="-8.24e-6" izz="2.56e-5" />
    </inertial>
    <visual>
      <origin xyz="0 0 0" rpy="0 0 0" />
      <geometry>
        <mesh filename="package://Go_manipulator_description/meshes/gripper_finger1.STL" />
      </geometry>
      <material name="black"/>
    </visual>
    <collision>
      <origin xyz="0 0 0" rpy="0 0 0" />
      <geometry>
        <mesh filename="package://Go_manipulator_description/meshes/gripper_finger1.STL" />
      </geometry>
    </collision>
  </link>

  <!-- Joint 7 -->
  <joint name="joint7" type="revolute">
    <origin xyz="-0.0509 0.0241 -0.0024" rpy="0 0 0" />
    <parent link="gripper_base" />
    <child link="gripper_finger1" />
    <axis xyz="1 0 0" />
    <limit lower="-0.2" upper="0.2" effort="100" velocity="0.1" />
  </joint>

  <!-- Gripper Finger 2 -->
  <link name="gripper_finger2">
    <inertial>
      <origin xyz="0.0518 0.0832 0.0141" rpy="0 0 0" />
      <mass value="0.0356" />
      <inertia ixx="4.53e-5" ixy="4.98e-7" ixz="2.22e-7" iyy="2.41e-5" iyz="-8.25e-6" izz="2.56e-5" />
    </inertial>
    <visual>
      <origin xyz="0 0 0" rpy="0 0 0" />
      <geometry>
        <mesh filename="package://Go_manipulator_description/meshes/gripper_finger2.STL" />
      </geometry>
      <material name="black"/>
    </visual>
    <collision>
      <origin xyz="0 0 0" rpy="0 0 0" />
      <geometry>
        <mesh filename="package://Go_manipulator_description/meshes/gripper_finger2.STL" />
      </geometry>
    </collision>
  </link>

  <!-- Joint 8 -->
  <joint name="joint8" type="revolute">
    <origin xyz="0.0509 0.0241 0.0019" rpy="0 0 3.1416" />
    <parent link="gripper_base" />
    <child link="gripper_finger2" />
    <axis xyz="1 0 0" />
    <mimic joint="joint7"/>
    <limit lower="-0.2" upper="0.2" effort="100" velocity="0.1" />
  </joint>


  <joint name="end_effector_joint" type="fixed">
    <parent link="link5"/>
    <child link="end_effector_link"/>
    <origin xyz="0.0 -0.288 0.0 " rpy="0 0 0"/>
  </joint>

  <link name="end_effector_link">
    <visual>
      <origin rpy="0 0 0" xyz="0 0 0"/>
      <geometry>
        <box size="0.01 0.01 0.01"/>
      </geometry>
      <material name="red"/>
    </visual>
  </link>



</robot>
